Workbook
Name scenario: 'Drivers'!$D$6
Name share_price: 'Drivers'!$D$7
Name valuation_date: 'Drivers'!$D$8
Name bs_date: 'Drivers'!$D$9
Name fy1_end: 'Drivers'!$D$10
Name exit_date: 'Drivers'!$D$11
Name exit_date2: 'Drivers'!$D$12
Name shares_diluted: 'Drivers'!$D$13
Name cash_bs: 'Drivers'!$D$14
Name total_debt: 'Drivers'!$D$15
Name net_debt: 'Drivers'!$D$16
Name fee_2026: 'Drivers'!$D$17
Name market_cap: 'Drivers'!$D$18
Name enterprise_value: 'Drivers'!$D$19
Name risk_free_rate: 'Drivers'!$D$22
Name beta: 'Drivers'!$D$23
Name equity_risk_premium: 'Drivers'!$D$24
Name cost_of_equity: 'Drivers'!$D$25
Name kd_pretax: 'Drivers'!$D$26
Name kd_tax: 'Drivers'!$D$27
Name debt_weight: 'Drivers'!$D$28
Name wacc_rate: 'Drivers'!$D$29
Name min_cash_months: 'Drivers'!$D$32
Name creep: 'Drivers'!$D$33
Name rep_px_2026: 'Drivers'!$D$34
Name rep_px_growth: 'Drivers'!$D$35
Name hurdle_irr: 'Drivers'!$D$36
Name wacc_step: 'Drivers'!$D$37
Name g_step: 'Drivers'!$D$38
Name pe_step: 'Drivers'!$D$39
Name prob_bear: 'Drivers'!$F$43
Name prob_base: 'Drivers'!$G$43
Name prob_bull: 'Drivers'!$H$43
Name tg_bear: 'Drivers'!$F$44
Name tg_base: 'Drivers'!$G$44
Name tg_bull: 'Drivers'!$H$44
Name exit_pe_bear: 'Drivers'!$F$45
Name exit_pe_base: 'Drivers'!$G$45
Name exit_pe_bull: 'Drivers'!$H$45
Name fy25_rev_ucan: 'Drivers'!$D$48
Name fy25_rev_emea: 'Drivers'!$D$49
Name fy25_rev_latam: 'Drivers'!$D$50
Name fy25_rev_apac: 'Drivers'!$D$51
Name cash_to_amort: 'Drivers'!$I$56:$R$56
Name da_pct: 'Drivers'!$I$57:$R$57
Name sbc_pct: 'Drivers'!$I$58:$R$58
Name capex_pct: 'Drivers'!$I$59:$R$59
Name wc_pct: 'Drivers'!$I$60:$R$60
Name tax_rate: 'Drivers'!$I$61:$R$61
Name int_rate: 'Drivers'!$I$62:$R$62
Name cash_yield: 'Drivers'!$I$63:$R$63
Name oneoff: 'Drivers'!$I$64:$R$64
Name gross_debt: 'Drivers'!$I$65:$R$65
Name g_ucan_bear: 'Drivers'!$I$69:$R$69
Name g_ucan_base: 'Drivers'!$I$70:$R$70
Name g_ucan_bull: 'Drivers'!$I$71:$R$71
Name g_emea_bear: 'Drivers'!$I$72:$R$72
Name g_emea_base: 'Drivers'!$I$73:$R$73
Name g_emea_bull: 'Drivers'!$I$74:$R$74
Name g_latam_bear: 'Drivers'!$I$75:$R$75

Sheet Summary
B1: Netflix, Inc. (NASDAQ: NFLX)
B2: Built 2026-10-23 after the Q3 2026 print, for a 2-3 year hold. Calendar fiscal year; shares post the 10-for-1 split.
B3: Blue = input Black = formula Green = cross-sheet link $ in millions except per share; shares in millions (post-split)
B5: MARKET
B6: Share price | C6: $ | D6: ='Drivers'!$D$7 | E6: ='Drivers'!$D$8
B7: Diluted shares | C7: mm | D7: ='Drivers'!$D$13
B8: Market capitalization | C8: $mm | D8: ='Drivers'!$D$18
B9: Net debt (9/30/26) | C9: $mm | D9: ='Drivers'!$D$16
B10: Enterprise value | C10: $mm | D10: ='Drivers'!$D$19
B11: P/E, FY26E ex the fee / FY27E (base) | C11: x | D11: ='Drivers'!$D$7/'Scenarios'!G14 | E11: ='Drivers'!$D$7/'Scenarios'!G15
B12: EV / EBIT, FY26E (base) | C12: x | D12: ='Scenarios'!D244
B13: Free cash flow yield, FY26E ex the fee (base) | C13: % | D13: ='Scenarios'!I208/'Drivers'!$D$18
B14: Buyback yield, FY26E (base) | C14: % | D14: =-'Scenarios'!I213/'Drivers'!$D$18
B15: Street price target, average / 10-year median P/E (Earnings Desk) | C15: $ | D15: ='Drivers'!$D$107 | E15: 55
B17: VALUE BY SCENARIO
D18: Bear | E18: Base | F18: Bull | G18: Weighted
B19: Probability | C19: % | D19: ='Scenarios'!F7 | E19: ='Scenarios'!G7 | F19: ='Scenarios'!H7
B20: DCF value per share | C20: $ | D20: ='Scenarios'!F24 | E20: ='Scenarios'!G24 | F20: ='Scenarios'!H24 | G20: ='Scenarios'!I24
B21: vs price | C21: % | D21: ='Scenarios'!F25 | E21: ='Scenarios'!G25 | F21: ='Scenarios'!H25 | G21: ='Scenarios'!I25
B22: FY26E EPS, GAAP (with the fee) | C22: $ | D22: ='Scenarios'!F13 | E22: ='Scenarios'!G13 | F22: ='Scenarios'!H13 | G22: ='Scenarios'!I13
B23: FY26E EPS ex the fee | C23: $ | D23: ='Scenarios'!F14 | E23: ='Scenarios'!G14 | F23: ='Scenarios'!H14 | G23: ='Scenarios'!I14
B24: FY27E EPS | C24: $ | D24: ='Scenarios'!F15 | E24: ='Scenarios'!G15 | F24: ='Scenarios'!H15 | G24: ='Scenarios'!I15
B25: FY29E EPS | C25: $ | D25: ='Scenarios'!F16 | E25: ='Scenarios'!G16 | F25: ='Scenarios'!H16 | G25: ='Scenarios'!I16
B26: Exit P/E (NTM) | C26: x | D26: ='Scenarios'!F26 | E26: ='Scenarios'!G26 | F26: ='Scenarios'!H26
B27: Price at the end of 2028 | C27: $ | D27: ='Scenarios'!F27 | E27: ='Scenarios'!G27 | F27: ='Scenarios'!H27 | G27: ='Scenarios'!I27
B28: IRR to the end of 2028 | C28: % | D28: ='Scenarios'!F28 | E28: ='Scenarios'!G28 | F28: ='Scenarios'!H28 | G28: ='Scenarios'!I28
B29: Price at the end of 2029 | C29: $ | D29: ='Scenarios'!F29 | E29: ='Scenarios'!G29 | F29: ='Scenarios'!H29 | G29: ='Scenarios'!I29
B30: IRR to the end of 2029 | C30: % | D30: ='Scenarios'!F30 | E30: ='Scenarios'!G30 | F30: ='Scenarios'!H30 | G30: ='Scenarios'!I30
B31: Entry price for the hurdle IRR to exit 1 | C31: $ | D31: ='Scenarios'!F31 | E31: ='Scenarios'!G31 | F31: ='Scenarios'!H31 | G31: ='Scenarios'!I31
B32: FY29E operating margin | C32: % | D32: ='Scenarios'!F12 | E32: ='Scenarios'!G12 | F32: ='Scenarios'!H12
B33: FY28E advertising revenue | C33: $mm | D33: ='Scenarios'!F10 | E33: ='Scenarios'!G10 | F33: ='Scenarios'!H10
B34: FY27E share repurchases | C34: $mm | D34: ='Scenarios'!F20 | E34: ='Scenarios'!G20 | F34: ='Scenarios'!H20
B35: Reward / risk, 2028 price path: (bull - price) / (price - bear) | C35: x | D35: =(F27-'Drivers'!$D$7)/('Drivers'!$D$7-D27)
B36: Reward / risk, DCF: (bull - price) / (price - bear) | C36: x | D36: =(F20-'Drivers'!$D$7)/('Drivers'!$D$7-D20)
B38: ESTIMATES, ACTIVE SCENARIO | C38: =CHOOSE('Drivers'!$D$6,"Bear","Base","Bull")
B39: Fiscal year | D39: 2025 | E39: 2026 | F39: 2027 | G39: 2028 | H39: 2029 | I39: 2030
B40: Revenue | C40: $mm | D40: ='Model'!H16 | E40: ='Model'!I16 | F40: ='Model'!J16 | G40: ='Model'!K16 | H40: ='Model'!L16 | I40: ='Model'!M16
B41: y/y | C41: % | D41: ='Model'!H17 | E41: ='Model'!I17 | F41: ='Model'!J17 | G41: ='Model'!K17 | H41: ='Model'!L17 | I41: ='Model'!M17
B42: Advertising revenue (memo) | C42: $mm | D42: ='Model'!H18 | E42: ='Model'!I18 | F42: ='Model'!J18 | G42: ='Model'!K18 | H42: ='Model'!L18 | I42: ='Model'!M18
B43: Content amortization growth | C43: % | D43: ='Model'!H25 | E43: ='Model'!I25 | F43: ='Model'!J25 | G43: ='Model'!K25 | H43: ='Model'!L25 | I43: ='Model'!M25
...

Sheet Drivers
B1: Netflix, Inc. | Drivers
B2: All inputs. FY25 10-K, Q3 2026 10-Q and shareholder letter (2026-10-20), market data 2026-10-23.
B3: Blue = input Black = formula Green = cross-sheet link $ in millions except per share; shares in millions (post-split)
B5: SCENARIO AND MARKET
B6: Active scenario (1 = Bear, 2 = Base, 3 = Bull) | C6: =CHOOSE(D6,"Bear","Base","Bull") | D6: 2 | E6: drives Model, Valuation and the Quarterly 4Q26E column; Scenarios and Summary values do not move
B7: Share price | C7: $ | D7: 66.29 | E7: Nasdaq close 2026-10-23; 52-week range $64.10 to $116.73; 10-for-1 split 2025-11-14
B8: Valuation date | D8: 46318 | E8: today
B9: Balance-sheet date used in the bridge | D9: 46295 | E9: Q3 2026 10-Q
B10: End of FY2026 | D10: 46387
B11: Exit date 1: end of 2028 | D11: 47118 | E11: multiple applied to 2029E EPS
B12: Exit date 2: end of 2029 | D12: 47483 | E12: multiple applied to 2030E EPS
B13: Diluted shares at 9/30/26 | C13: mm | D13: 4184 | E13: 4,106.3 basic on the 10-Q cover + ~78 dilutive (Q3 basic $0.89 vs diluted $0.87)
B14: Cash and short-term investments | C14: $mm | D14: 8223 | E14: 9/30/26: 8,194 + 29
B15: Gross debt (senior notes at par) | C15: $mm | D15: 15337 | E15: 9/30/26: $15,337mm par, carrying $15,132mm; EUR 4,700mm; $3B revolver and $3B CP undrawn
B16: Net debt | C16: $mm | D16: =D15-D14 | E16: the letter's non-GAAP net debt $7.1B
B17: WBD termination fee received, Q1 2026 (pre-tax) | C17: $mm | D17: 2800 | E17: paid by Paramount Skydance on WBD's behalf; booked in interest and other income
B18: Market capitalization | C18: $mm | D18: =D7*D13
B19: Enterprise value | C19: $mm | D19: =D18+D16
B21: COST OF CAPITAL
B22: Risk-free rate | C22: % | D22: 0.0499 | E22: UST 10Y, 2026-10-23
B23: Beta | C23: x | D23: 1.25 | E23: judgment: 5y regression 1.61 carries the 2022 drawdown; 2y nearer 1.1
B24: Equity risk premium | C24: % | D24: 0.05 | E24: judgment, desk convention
B25: Cost of equity | C25: % | D25: =D22+D23*D24
B26: Pre-tax cost of debt | C26: % | D26: 0.053 | E26: Aug 2026 notes: 5.25% 2036, 5.40% 2054
B27: Tax shield rate | C27: % | D27: 0.165
B28: Debt / (debt + market cap) | C28: % | D28: =D15/(D15+D18)
B29: WACC | C29: % | D29: =(1-D28)*D25+D28*D26*(1-D27)
B31: CASH AND CAPITAL CONVENTIONS
B32: Cash held, months of revenue | C32: mo | D32: 2 | E32: management's rule of thumb is about two months; 9/30/26 held 1.9 months
B33: Share creep before buybacks | C33: %/yr | D33: 0.004 | E33: equity-comp dilution
B34: 2026 blended repurchase price | C34: $ | D34: 82 | E34: 9M actual $85 (127mm shares, $10.8B); Q4 near the current price
B35: Repurchase price growth after 2026 | C35: %/yr | D35: 0.08 | E35: buybacks execute at today's price compounded
B36: Hurdle IRR for the entry price | C36: % | D36: 0.15 | E36: what the hold has to earn
B37: Sensitivity step, WACC | C37: % | D37: 0.0075
B38: Sensitivity step, terminal growth | C38: % | D38: 0.005
B39: Sensitivity step, exit P/E | C39: x | D39: 2
B41: SCENARIO SCALARS
D42: Active | F42: Bear | G42: Base | H42: Bull
B43: Probability | C43: % | D43: =CHOOSE($D$6,F43,G43,H43) | F43: 0.25 | G43: 0.5 | H43: 0.25 | I43: judgment
B44: Terminal growth | C44: % | D44: =CHOOSE($D$6,F44,G44,H44) | F44: 0.025 | G44: 0.03 | H44: 0.035 | I44: judgment
...

Sheet Quarterly
B1: Netflix, Inc. | Quarterly
B2: 2025 quarters, 1Q-3Q 2026A, and the 4Q26 the active scenario implies, against the Q4 guide.
B3: Blue = input Black = formula Green = cross-sheet link $ in millions except per share; shares in millions (post-split)
B5: Revenue | D5: 1Q25A | E5: 2Q25A | F5: 3Q25A | G5: 4Q25A | H5: FY25A | I5: 1Q26A | J5: 2Q26A | K5: 3Q26A | L5: 4Q26E | M5: FY26E | N5: y/y | O5: Q4 guide
B6: United States and Canada | C6: $mm | D6: 4617 | E6: 4929 | F6: 5072 | G6: 5339 | H6: =SUM(D6:G6) | I6: 5245 | J6: 5432 | K6: 5628 | L6: =M6-I6-J6-K6 | M6: ='Model'!I7 | N6: =M6/H6-1
B7: Europe, Middle East and Africa | C7: $mm | D7: 3405 | E7: 3538 | F7: 3699 | G7: 3873 | H7: =SUM(D7:G7) | I7: 3998 | J7: 4034 | K7: 4107 | L7: =M7-I7-J7-K7 | M7: ='Model'!I9 | N7: =M7/H7-1
B8: Latin America | C8: $mm | D8: 1262 | E8: 1307 | F8: 1371 | G8: 1418 | H8: =SUM(D8:G8) | I8: 1497 | J8: 1584 | K8: 1603 | L8: =M8-I8-J8-K8 | M8: ='Model'!I11 | N8: =M8/H8-1
B9: Asia-Pacific | C9: $mm | D9: 1259 | E9: 1305 | F9: 1369 | G9: 1421 | H9: =SUM(D9:G9) | I9: 1509 | J9: 1510 | K9: 1537 | L9: =M9-I9-J9-K9 | M9: ='Model'!I13 | N9: =M9/H9-1
B10: Total revenue | C10: $mm | D10: =D6+D7+D8+D9 | E10: =E6+E7+E8+E9 | F10: =F6+F7+F8+F9 | G10: =G6+G7+G8+G9 | H10: =H6+H7+H8+H9 | I10: =I6+I7+I8+I9 | J10: =J6+J7+J8+J9 | K10: =K6+K7+K8+K9 | L10: =M10-I10-J10-K10 | M10: ='Model'!I16 | N10: =M10/H10-1 | O10: ='Drivers'!$D$100
B11: y/y | C11: % | I11: =I10/D10-1 | J11: =J10/E10-1 | K11: =K10/F10-1 | L11: =L10/G10-1 | M11: =M10/H10-1 | O11: =O10/G10-1
B13: INCOME STATEMENT
B14: Cost of revenues (incl. content amortization) | C14: $mm | D14: 5263 | E14: 5325 | F14: 6164 | G14: 6523 | H14: =SUM(D14:G14) | I14: 5888 | J14: 6037 | K14: 6079 | L14: =M14-I14-J14-K14 | M14: ='Model'!I24+'Model'!I27 | N14: =M14/H14-1
B15: Sales and marketing | C15: $mm | D15: 688 | E15: 713 | F15: 786 | G15: 1114 | H15: =SUM(D15:G15) | I15: 842 | J15: 824 | K15: 837
B16: Technology and development | C16: $mm | D16: 823 | E16: 825 | F16: 854 | G16: 890 | H16: =SUM(D16:G16) | I16: 960 | J16: 1008 | K16: 1033
B17: General and administrative | C17: $mm | D17: 421 | E17: 441 | F17: 458 | G17: 568 | H17: =SUM(D17:G17) | I17: 603 | J17: 499 | K17: 466
B18: Operating expenses | C18: $mm | D18: =D15+D16+D17 | E18: =E15+E16+E17 | F18: =F15+F16+F17 | G18: =G15+G16+G17 | H18: =H15+H16+H17 | I18: =I15+I16+I17 | J18: =J15+J16+J17 | K18: =K15+K16+K17 | L18: =M18-I18-J18-K18 | M18: ='Model'!I31 | N18: =M18/H18-1
B19: Operating income | C19: $mm | D19: =D10-D14-D18 | E19: =E10-E14-E18 | F19: =F10-F14-F18 | G19: =G10-G14-G18 | H19: =H10-H14-H18 | I19: =I10-I14-I18 | J19: =J10-J14-J18 | K19: =K10-K14-K18 | L19: =M19-I19-J19-K19 | M19: ='Model'!I33 | N19: =M19/H19-1 | O19: ='Drivers'!$D$101
B20: operating margin | C20: % | D20: =D19/D10 | E20: =E19/E10 | F20: =F19/F10 | G20: =G19/G10 | H20: =H19/H10 | I20: =I19/I10 | J20: =J19/J10 | K20: =K19/K10 | ... M20: =M19/M10 | O20: =O19/O10
B21: Operating income, reported (memo) | C21: $mm | D21: 3347 | E21: 3775 | F21: 3248 | G21: 2957 | H21: =SUM(D21:G21) | I21: 3957 | J21: 4193 | K21: 4459
B22: Interest and other, net (1Q26 includes the $2.8B fee) | C22: $mm | D22: -133 | E22: -143 | F22: -139 | G22: -189 | H22: =SUM(D22:G22) | I22: 2590 | J22: -124 | K22: -142 | L22: =M22-I22-J22-K22 | M22: ='Model'!I36+'Model'!I37 | N22: =M22/H22-1
B23: Income before income taxes | C23: $mm | D23: =D19+D22 | E23: =E19+E22 | F23: =F19+F22 | G23: =G19+G22 | H23: =H19+H22 | I23: =I19+I22 | J23: =J19+J22 | K23: =K19+K22 | L23: =M23-I23-J23-K23 | M23: =M19+M22 | N23: =M23/H23-1
B24: Provision for income taxes | C24: $mm | D24: 323 | E24: 506 | F24: 562 | G24: 349 | H24: =SUM(D24:G24) | I24: 1264 | J24: 667 | K24: 653 | L24: =M24-I24-J24-K24 | M24: ='Model'!I40 | N24: =M24/H24-1
B25: Net income | C25: $mm | D25: =D23-D24 | E25: =E23-E24 | F25: =F23-F24 | G25: =G23-G24 | H25: =H23-H24 | I25: =I23-I24 | J25: =J23-J24 | K25: =K23-K24 | L25: =M25-I25-J25-K25 | M25: =M23-M24 | N25: =M25/H25-1 | O25: 2787
B26: Net income, reported (memo) | C26: $mm | D26: 2890 | E26: 3125 | F26: 2547 | G26: 2419 | H26: =SUM(D26:G26) | I26: 5283 | J26: 3401 | K26: 3664
B27: Diluted shares | C27: mm | D27: 4369.6 | E27: 4348.8 | F27: 4340.4 | G27: 4330 | H27: 4344 | I27: 4298.4 | J27: 4261.3 | K27: 4195.1 | L27: ='Model'!I73 | M27: ='Model'!I44
B28: Diluted EPS, GAAP | C28: $ | D28: =D25/D27 | E28: =E25/E27 | F28: =F25/F27 | G28: =G25/G27 | H28: =H25/H27 | I28: =I25/I27 | J28: =J25/J27 | K28: =K25/K27 | ... M28: =M25/M27 | N28: =M28/H28-1 | O28: ='Drivers'!$D$102
B29: Diluted EPS, reported (memo) | C29: $ | D29: 0.66 | E29: 0.72 | F29: 0.59 | G29: 0.56 | H29: 2.53 | I29: 1.23 | J29: 0.8 | K29: 0.87
B31: CASH FLOW
B32: Free cash flow (company definition) | C32: $mm | D32: 2661 | E32: 2273 | F32: 2660 | G32: 1867 | H32: =SUM(D32:G32) | I32: 5094 | J32: 1525 | K32: 2884 | L32: =M32-I32-J32-K32 | M32: ='Model'!I61 | N32: =M32/H32-1 | O32: ='Drivers'!$D$97-I32-J32-K32 | P32: Q4 guide column = FY guide $12.0B less 9M actual
B33: Share repurchases (cash paid) | C33: $mm | D33: 3536 | E33: 1654 | F33: 1857 | G33: 2080 | H33: =SUM(D33:G33) | I33: 1271 | J33: 4714 | K33: 4797 | L33: =M33-I33-J33-K33 | M33: =-'Model'!I68 | N33: =M33/H33-1
B34: Cash content spend / amortization, nine months | C34: x | H34: =12039/11658 | K34: =14934/12765 | M34: ='Model'!I54 | P34: 9M26 additions 14,934 / amortization 12,765; FY guide ~1.1x

Sheet Model
B1: Netflix, Inc. | Model
B2: ="Active scenario: "&CHOOSE('Drivers'!$D$6,"Bear","Base","Bull")&". FY2023A to FY2025A reported, FY2026E to FY2035E forecast. Calendar years."
B3: Blue = input Black = formula Green = cross-sheet link $ in millions except per share; shares in millions (post-split)
B5: REVENUE | ACTIVE SCENARIO
B6: Fiscal year (calendar) | F6: 2023 | G6: 2024 | H6: 2025 | I6: 2026 | J6: 2027 | K6: 2028 | L6: 2029 | M6: 2030 | N6: 2031 | O6: 2032 | P6: 2033 | Q6: 2034 | R6: 2035
B7: United States and Canada | C7: $mm | F7: 14874 | G7: 17359 | H7: ='Drivers'!$D$48 | I7: =H7*(1+I8) | J7: =I7*(1+J8) | K7: =J7*(1+K8) | L7: =K7*(1+L8) | M7: =L7*(1+M8) | N7: =M7*(1+N8) | O7: =N7*(1+O8) | P7: =O7*(1+P8) | ... R7: =Q7*(1+R8)
B8: y/y | C8: % | G8: =G7/F7-1 | H8: =H7/G7-1 | I8: =CHOOSE('Drivers'!$D$6,'Drivers'!I$69,'Drivers'!I$70,'Drivers'!I$71) | J8: =CHOOSE('Drivers'!$D$6,'Drivers'!J$69,'Drivers'!J$70,'Drivers'!J$71) | K8: =CHOOSE('Drivers'!$D$6,'Drivers'!K$69,'Drivers'!K$70,'Drivers'!K$71) | L8: =CHOOSE('Drivers'!$D$6,'Drivers'!L$69,'Drivers'!L$70,'Drivers'!L$71) | M8: =CHOOSE('Drivers'!$D$6,'Drivers'!M$69,'Drivers'!M$70,'Drivers'!M$71) | N8: =CHOOSE('Drivers'!$D$6,'Drivers'!N$69,'Drivers'!N$70,'Drivers'!N$71) | O8: =CHOOSE('Drivers'!$D$6,'Drivers'!O$69,'Drivers'!O$70,'Drivers'!O$71) | P8: =CHOOSE('Drivers'!$D$6,'Drivers'!P$69,'Drivers'!P$70,'Drivers'!P$71) | ... R8: =CHOOSE('Drivers'!$D$6,'Drivers'!R$69,'Drivers'!R$70,'Drivers'!R$71)
B9: Europe, Middle East and Africa | C9: $mm | F9: 10556 | G9: 12387 | H9: ='Drivers'!$D$49 | I9: =H9*(1+I10) | J9: =I9*(1+J10) | K9: =J9*(1+K10) | L9: =K9*(1+L10) | M9: =L9*(1+M10) | N9: =M9*(1+N10) | O9: =N9*(1+O10) | P9: =O9*(1+P10) | ... R9: =Q9*(1+R10)
B10: y/y | C10: % | G10: =G9/F9-1 | H10: =H9/G9-1 | I10: =CHOOSE('Drivers'!$D$6,'Drivers'!I$72,'Drivers'!I$73,'Drivers'!I$74) | J10: =CHOOSE('Drivers'!$D$6,'Drivers'!J$72,'Drivers'!J$73,'Drivers'!J$74) | K10: =CHOOSE('Drivers'!$D$6,'Drivers'!K$72,'Drivers'!K$73,'Drivers'!K$74) | L10: =CHOOSE('Drivers'!$D$6,'Drivers'!L$72,'Drivers'!L$73,'Drivers'!L$74) | M10: =CHOOSE('Drivers'!$D$6,'Drivers'!M$72,'Drivers'!M$73,'Drivers'!M$74) | N10: =CHOOSE('Drivers'!$D$6,'Drivers'!N$72,'Drivers'!N$73,'Drivers'!N$74) | O10: =CHOOSE('Drivers'!$D$6,'Drivers'!O$72,'Drivers'!O$73,'Drivers'!O$74) | P10: =CHOOSE('Drivers'!$D$6,'Drivers'!P$72,'Drivers'!P$73,'Drivers'!P$74) | ... R10: =CHOOSE('Drivers'!$D$6,'Drivers'!R$72,'Drivers'!R$73,'Drivers'!R$74)
B11: Latin America | C11: $mm | F11: 4446 | G11: 4840 | H11: ='Drivers'!$D$50 | I11: =H11*(1+I12) | J11: =I11*(1+J12) | K11: =J11*(1+K12) | L11: =K11*(1+L12) | M11: =L11*(1+M12) | N11: =M11*(1+N12) | O11: =N11*(1+O12) | P11: =O11*(1+P12) | ... R11: =Q11*(1+R12)
B12: y/y | C12: % | G12: =G11/F11-1 | H12: =H11/G11-1 | I12: =CHOOSE('Drivers'!$D$6,'Drivers'!I$75,'Drivers'!I$76,'Drivers'!I$77) | J12: =CHOOSE('Drivers'!$D$6,'Drivers'!J$75,'Drivers'!J$76,'Drivers'!J$77) | K12: =CHOOSE('Drivers'!$D$6,'Drivers'!K$75,'Drivers'!K$76,'Drivers'!K$77) | L12: =CHOOSE('Drivers'!$D$6,'Drivers'!L$75,'Drivers'!L$76,'Drivers'!L$77) | M12: =CHOOSE('Drivers'!$D$6,'Drivers'!M$75,'Drivers'!M$76,'Drivers'!M$77) | N12: =CHOOSE('Drivers'!$D$6,'Drivers'!N$75,'Drivers'!N$76,'Drivers'!N$77) | O12: =CHOOSE('Drivers'!$D$6,'Drivers'!O$75,'Drivers'!O$76,'Drivers'!O$77) | P12: =CHOOSE('Drivers'!$D$6,'Drivers'!P$75,'Drivers'!P$76,'Drivers'!P$77) | ... R12: =CHOOSE('Drivers'!$D$6,'Drivers'!R$75,'Drivers'!R$76,'Drivers'!R$77)
B13: Asia-Pacific | C13: $mm | F13: 3764 | G13: 4415 | H13: ='Drivers'!$D$51 | I13: =H13*(1+I14) | J13: =I13*(1+J14) | K13: =J13*(1+K14) | L13: =K13*(1+L14) | M13: =L13*(1+M14) | N13: =M13*(1+N14) | O13: =N13*(1+O14) | P13: =O13*(1+P14) | ... R13: =Q13*(1+R14)
B14: y/y | C14: % | G14: =G13/F13-1 | H14: =H13/G13-1 | I14: =CHOOSE('Drivers'!$D$6,'Drivers'!I$78,'Drivers'!I$79,'Drivers'!I$80) | J14: =CHOOSE('Drivers'!$D$6,'Drivers'!J$78,'Drivers'!J$79,'Drivers'!J$80) | K14: =CHOOSE('Drivers'!$D$6,'Drivers'!K$78,'Drivers'!K$79,'Drivers'!K$80) | L14: =CHOOSE('Drivers'!$D$6,'Drivers'!L$78,'Drivers'!L$79,'Drivers'!L$80) | M14: =CHOOSE('Drivers'!$D$6,'Drivers'!M$78,'Drivers'!M$79,'Drivers'!M$80) | N14: =CHOOSE('Drivers'!$D$6,'Drivers'!N$78,'Drivers'!N$79,'Drivers'!N$80) | O14: =CHOOSE('Drivers'!$D$6,'Drivers'!O$78,'Drivers'!O$79,'Drivers'!O$80) | P14: =CHOOSE('Drivers'!$D$6,'Drivers'!P$78,'Drivers'!P$79,'Drivers'!P$80) | ... R14: =CHOOSE('Drivers'!$D$6,'Drivers'!R$78,'Drivers'!R$79,'Drivers'!R$80)
B15: DVD (wound down 2023) | C15: $mm | F15: 83 | G15: 0 | H15: 0 | I15: =0 | J15: =0 | K15: =0 | L15: =0 | M15: =0 | N15: =0 | O15: =0 | P15: =0 | ... R15: =0
B16: Total revenue | C16: $mm | F16: =F7+F9+F11+F13+F15 | G16: =G7+G9+G11+G13+G15 | H16: =H7+H9+H11+H13+H15 | I16: =I7+I9+I11+I13+I15 | J16: =J7+J9+J11+J13+J15 | K16: =K7+K9+K11+K13+K15 | L16: =L7+L9+L11+L13+L15 | M16: =M7+M9+M11+M13+M15 | ... R16: =R7+R9+R11+R13+R15
B17: y/y | C17: % | G17: =G16/F16-1 | H17: =H16/G16-1 | I17: =I16/H16-1 | J17: =J16/I16-1 | K17: =K16/J16-1 | L17: =L16/K16-1 | M17: =M16/L16-1 | N17: =N16/M16-1 | ... R17: =R16/Q16-1
B18: of which advertising (memo) | C18: $mm | G18: 600 | H18: 1500 | I18: =CHOOSE('Drivers'!$D$6,'Drivers'!I$81,'Drivers'!I$82,'Drivers'!I$83) | J18: =CHOOSE('Drivers'!$D$6,'Drivers'!J$81,'Drivers'!J$82,'Drivers'!J$83) | K18: =CHOOSE('Drivers'!$D$6,'Drivers'!K$81,'Drivers'!K$82,'Drivers'!K$83) | L18: =CHOOSE('Drivers'!$D$6,'Drivers'!L$81,'Drivers'!L$82,'Drivers'!L$83) | M18: =CHOOSE('Drivers'!$D$6,'Drivers'!M$81,'Drivers'!M$82,'Drivers'!M$83) | N18: =CHOOSE('Drivers'!$D$6,'Drivers'!N$81,'Drivers'!N$82,'Drivers'!N$83) | O18: =CHOOSE('Drivers'!$D$6,'Drivers'!O$81,'Drivers'!O$82,'Drivers'!O$83) | P18: =CHOOSE('Drivers'!$D$6,'Drivers'!P$81,'Drivers'!P$82,'Drivers'!P$83) | ... R18: =CHOOSE('Drivers'!$D$6,'Drivers'!R$81,'Drivers'!R$82,'Drivers'!R$83)
B19: advertising, % of revenue | C19: % | G19: =G18/G16 | H19: =H18/H16 | I19: =I18/I16 | J19: =J18/J16 | K19: =K18/K16 | L19: =L18/L16 | M19: =M18/M16 | N19: =N18/N16 | ... R19: =R18/R16
B20: subscription and other (memo) | C20: $mm | G20: =G16-G18 | H20: =H16-H18 | I20: =I16-I18 | J20: =J16-J18 | K20: =K16-K18 | L20: =L16-L18 | M20: =M16-M18 | N20: =N16-N18 | ... R20: =R16-R18
B21: y/y | C21: % | H21: =H20/G20-1 | I21: =I20/H20-1 | J21: =J20/I20-1 | K21: =K20/J20-1 | L21: =L20/K20-1 | M21: =M20/L20-1 | N21: =N20/M20-1 | O21: =O20/N20-1 | ... R21: =R20/Q20-1
B23: INCOME STATEMENT
B24: Content amortization | C24: $mm | F24: 14197 | G24: 15302 | H24: 16422 | I24: =H24*(1+I25) | J24: =I24*(1+J25) | K24: =J24*(1+K25) | L24: =K24*(1+L25) | M24: =L24*(1+M25) | N24: =M24*(1+N25) | O24: =N24*(1+O25) | P24: =O24*(1+P25) | ... R24: =Q24*(1+R25)
B25: y/y | C25: % | G25: =G24/F24-1 | H25: =H24/G24-1 | I25: =CHOOSE('Drivers'!$D$6,'Drivers'!I$84,'Drivers'!I$85,'Drivers'!I$86) | J25: =CHOOSE('Drivers'!$D$6,'Drivers'!J$84,'Drivers'!J$85,'Drivers'!J$86) | K25: =CHOOSE('Drivers'!$D$6,'Drivers'!K$84,'Drivers'!K$85,'Drivers'!K$86) | L25: =CHOOSE('Drivers'!$D$6,'Drivers'!L$84,'Drivers'!L$85,'Drivers'!L$86) | M25: =CHOOSE('Drivers'!$D$6,'Drivers'!M$84,'Drivers'!M$85,'Drivers'!M$86) | N25: =CHOOSE('Drivers'!$D$6,'Drivers'!N$84,'Drivers'!N$85,'Drivers'!N$86) | O25: =CHOOSE('Drivers'!$D$6,'Drivers'!O$84,'Drivers'!O$85,'Drivers'!O$86) | P25: =CHOOSE('Drivers'!$D$6,'Drivers'!P$84,'Drivers'!P$85,'Drivers'!P$86) | ... R25: =CHOOSE('Drivers'!$D$6,'Drivers'!R$84,'Drivers'!R$85,'Drivers'!R$86)
B26: % of revenue | C26: % | F26: =F24/F16 | G26: =G24/G16 | H26: =H24/H16 | I26: =I24/I16 | J26: =J24/J16 | K26: =K24/K16 | L26: =L24/L16 | M26: =M24/M16 | ... R26: =R24/R16
B27: Other cost of revenues | C27: $mm | F27: =19715-14197 | G27: =21038-15302 | H27: =23275-16422 | I27: =I16*I28 | J27: =J16*J28 | K27: =K16*K28 | L27: =L16*L28 | M27: =M16*M28 | N27: =N16*N28 | O27: =O16*O28 | P27: =P16*P28 | ... R27: =R16*R28
B28: % of revenue | C28: % | F28: =F27/F16 | G28: =G27/G16 | H28: =H27/H16 | I28: =CHOOSE('Drivers'!$D$6,'Drivers'!I$87,'Drivers'!I$88,'Drivers'!I$89) | J28: =CHOOSE('Drivers'!$D$6,'Drivers'!J$87,'Drivers'!J$88,'Drivers'!J$89) | K28: =CHOOSE('Drivers'!$D$6,'Drivers'!K$87,'Drivers'!K$88,'Drivers'!K$89) | L28: =CHOOSE('Drivers'!$D$6,'Drivers'!L$87,'Drivers'!L$88,'Drivers'!L$89) | M28: =CHOOSE('Drivers'!$D$6,'Drivers'!M$87,'Drivers'!M$88,'Drivers'!M$89) | N28: =CHOOSE('Drivers'!$D$6,'Drivers'!N$87,'Drivers'!N$88,'Drivers'!N$89) | O28: =CHOOSE('Drivers'!$D$6,'Drivers'!O$87,'Drivers'!O$88,'Drivers'!O$89) | P28: =CHOOSE('Drivers'!$D$6,'Drivers'!P$87,'Drivers'!P$88,'Drivers'!P$89) | ... R28: =CHOOSE('Drivers'!$D$6,'Drivers'!R$87,'Drivers'!R$88,'Drivers'!R$89)
B29: Gross profit | C29: $mm | F29: =F16-F24-F27 | G29: =G16-G24-G27 | H29: =H16-H24-H27 | I29: =I16-I24-I27 | J29: =J16-J24-J27 | K29: =K16-K24-K27 | L29: =L16-L24-L27 | M29: =M16-M24-M27 | ... R29: =R16-R24-R27
B30: gross margin | C30: % | F30: =F29/F16 | G30: =G29/G16 | H30: =H29/H16 | I30: =I29/I16 | J30: =J29/J16 | K30: =K29/K16 | L30: =L29/L16 | M30: =M29/M16 | ... R30: =R29/R16
B31: Operating expenses (sales and marketing, technology, G&A) | C31: $mm | F31: =2658+2676+1720 | G31: =2918+2925+1702 | H31: =3301+3391+1888 | I31: =I16*I32 | J31: =J16*J32 | K31: =K16*K32 | L31: =L16*L32 | M31: =M16*M32 | N31: =N16*N32 | O31: =O16*O32 | P31: =P16*P32 | ... R31: =R16*R32
B32: % of revenue | C32: % | F32: =F31/F16 | G32: =G31/G16 | H32: =H31/H16 | I32: =CHOOSE('Drivers'!$D$6,'Drivers'!I$90,'Drivers'!I$91,'Drivers'!I$92) | J32: =CHOOSE('Drivers'!$D$6,'Drivers'!J$90,'Drivers'!J$91,'Drivers'!J$92) | K32: =CHOOSE('Drivers'!$D$6,'Drivers'!K$90,'Drivers'!K$91,'Drivers'!K$92) | L32: =CHOOSE('Drivers'!$D$6,'Drivers'!L$90,'Drivers'!L$91,'Drivers'!L$92) | M32: =CHOOSE('Drivers'!$D$6,'Drivers'!M$90,'Drivers'!M$91,'Drivers'!M$92) | N32: =CHOOSE('Drivers'!$D$6,'Drivers'!N$90,'Drivers'!N$91,'Drivers'!N$92) | O32: =CHOOSE('Drivers'!$D$6,'Drivers'!O$90,'Drivers'!O$91,'Drivers'!O$92) | P32: =CHOOSE('Drivers'!$D$6,'Drivers'!P$90,'Drivers'!P$91,'Drivers'!P$92) | ... R32: =CHOOSE('Drivers'!$D$6,'Drivers'!R$90,'Drivers'!R$91,'Drivers'!R$92)
B33: Operating income | C33: $mm | F33: =F29-F31 | G33: =G29-G31 | H33: =H29-H31 | I33: =I29-I31 | J33: =J29-J31 | K33: =K29-K31 | L33: =L29-L31 | M33: =M29-M31 | ... R33: =R29-R31
B34: operating margin | C34: % | F34: =F33/F16 | G34: =G33/G16 | H34: =H33/H16 | I34: =I33/I16 | J34: =J33/J16 | K34: =K33/K16 | L34: =L33/L16 | M34: =M33/M16 | ... R34: =R33/R16
B35: y/y | C35: % | G35: =G33/F33-1 | H35: =H33/G33-1 | I35: =I33/H33-1 | J35: =J33/I33-1 | K35: =K33/J33-1 | L35: =L33/K33-1 | M35: =M33/L33-1 | N35: =N33/M33-1 | ... R35: =R33/Q33-1
B36: Interest expense | C36: $mm | F36: -700 | G36: -719 | H36: -777 | I36: =-H66*'Drivers'!I$62 | J36: =-I66*'Drivers'!J$62 | K36: =-J66*'Drivers'!K$62 | L36: =-K66*'Drivers'!L$62 | M36: =-L66*'Drivers'!M$62 | N36: =-M66*'Drivers'!N$62 | O36: =-N66*'Drivers'!O$62 | P36: =-O66*'Drivers'!P$62 | ... R36: =-Q66*'Drivers'!R$62
B37: Interest and other income (expense) | C37: $mm | F37: -49 | G37: 267 | H37: 172 | I37: =I64*'Drivers'!I$63+I38 | J37: =J64*'Drivers'!J$63+J38 | K37: =K64*'Drivers'!K$63+K38 | L37: =L64*'Drivers'!L$63+L38 | M37: =M64*'Drivers'!M$63+M38 | N37: =N64*'Drivers'!N$63+N38 | O37: =O64*'Drivers'!O$63+O38 | P37: =P64*'Drivers'!P$63+P38 | ... R37: =R64*'Drivers'!R$63+R38
B38: of which one-off (WBD termination fee) | C38: $mm | F38: 0 | G38: 0 | H38: 0 | I38: ='Drivers'!I$64 | J38: ='Drivers'!J$64 | K38: ='Drivers'!K$64 | L38: ='Drivers'!L$64 | M38: ='Drivers'!M$64 | N38: ='Drivers'!N$64 | O38: ='Drivers'!O$64 | P38: ='Drivers'!P$64 | ... R38: ='Drivers'!R$64
B39: Income before income taxes | C39: $mm | F39: =F33+F36+F37 | G39: =G33+G36+G37 | H39: =H33+H36+H37 | I39: =I33+I36+I37 | J39: =J33+J36+J37 | K39: =K33+K36+K37 | L39: =L33+L36+L37 | M39: =M33+M36+M37 | ... R39: =R33+R36+R37
B40: Provision for income taxes | C40: $mm | F40: 797 | G40: 1254 | H40: 1741 | I40: =I39*I41 | J40: =J39*J41 | K40: =K39*K41 | L40: =L39*L41 | M40: =M39*M41 | N40: =N39*N41 | O40: =O39*O41 | P40: =P39*P41 | ... R40: =R39*R41
B41: effective tax rate | C41: % | F41: =F40/F39 | G41: =G40/G39 | H41: =H40/H39 | I41: ='Drivers'!I$61 | J41: ='Drivers'!J$61 | K41: ='Drivers'!K$61 | L41: ='Drivers'!L$61 | M41: ='Drivers'!M$61 | N41: ='Drivers'!N$61 | O41: ='Drivers'!O$61 | P41: ='Drivers'!P$61 | ... R41: ='Drivers'!R$61
B42: Net income | C42: $mm | F42: =F39-F40 | G42: =G39-G40 | H42: =H39-H40 | I42: =I39-I40 | J42: =J39-J40 | K42: =K39-K40 | L42: =L39-L40 | M42: =M39-M40 | ... R42: =R39-R40
...

Sheet Valuation
B1: Netflix, Inc. | Valuation
B2: ="Active scenario: "&CHOOSE('Drivers'!$D$6,"Bear","Base","Bull")&". Cash flows after the 9/30/2026 balance sheet, discounted to the valuation date at mid-period. Price path at two horizons; no dividend."
B3: Blue = input Black = formula Green = cross-sheet link $ in millions except per share; shares in millions (post-split)
B5: DISCOUNTED CASH FLOW | ACTIVE SCENARIO
B6: Fiscal year (calendar) | F6: 2023 | G6: 2024 | H6: 2025 | I6: 2026 | J6: 2027 | K6: 2028 | L6: 2029 | M6: 2030 | N6: 2031 | O6: 2032 | P6: 2033 | Q6: 2034 | R6: 2035
B7: Unlevered free cash flow | C7: $mm | I7: ='Model'!I59 | J7: ='Model'!J59 | K7: ='Model'!K59 | L7: ='Model'!L59 | M7: ='Model'!M59 | N7: ='Model'!N59 | O7: ='Model'!O59 | P7: ='Model'!P59 | ... R7: ='Model'!R59
B8: Share of the year after the balance-sheet date | C8: x | I8: =('Drivers'!$D$10-'Drivers'!$D$9)/365 | J8: =1 | K8: =1 | L8: =1 | M8: =1 | N8: =1 | O8: =1 | P8: =1 | Q8: =1 | R8: =1
B9: Cash flow counted | C9: $mm | I9: =I7*I8 | J9: =J7*J8 | K9: =K7*K8 | L9: =L7*L8 | M9: =M7*M8 | N9: =N7*N8 | O9: =O7*O8 | P9: =P7*P8 | ... R9: =R7*R8
B10: Discount period, mid-period | C10: yrs | I10: =(('Drivers'!$D$10-'Drivers'!$D$9)/2+('Drivers'!$D$9-'Drivers'!$D$8))/365 | J10: =('Drivers'!$D$10-'Drivers'!$D$8)/365+0.5 | K10: =J10+1 | L10: =K10+1 | M10: =L10+1 | N10: =M10+1 | O10: =N10+1 | P10: =O10+1 | Q10: =P10+1 | R10: =Q10+1
B11: Discount factor | C11: x | I11: =1/(1+'Drivers'!$D$29)^I10 | J11: =1/(1+'Drivers'!$D$29)^J10 | K11: =1/(1+'Drivers'!$D$29)^K10 | L11: =1/(1+'Drivers'!$D$29)^L10 | M11: =1/(1+'Drivers'!$D$29)^M10 | N11: =1/(1+'Drivers'!$D$29)^N10 | O11: =1/(1+'Drivers'!$D$29)^O10 | P11: =1/(1+'Drivers'!$D$29)^P10 | ... R11: =1/(1+'Drivers'!$D$29)^R10
B12: Present value | C12: $mm | I12: =I9*I11 | J12: =J9*J11 | K12: =K9*K11 | L12: =L9*L11 | M12: =M9*M11 | N12: =N9*N11 | O12: =O9*O11 | P12: =P9*P11 | ... R12: =R9*R11
B14: PV of forecast cash flows | C14: $mm | D14: =SUM(I12:R12)
B15: Terminal growth | C15: % | D15: ='Drivers'!$D$44
B16: Terminal value at FY2035 | C16: $mm | D16: =R7*(1+D15)/('Drivers'!$D$29-D15)
B17: PV of terminal value | C17: $mm | D17: =D16*R11
B18: Enterprise value | C18: $mm | D18: =D14+D17
B19: Less: net debt at 9/30/2026 | C19: $mm | D19: =-'Drivers'!$D$16
B20: Equity value | C20: $mm | D20: =D18+D19
B21: Diluted shares | C21: mm | D21: ='Drivers'!$D$13
B22: DCF value per share | C22: $ | D22: =D20/D21
B23: Upside / (downside) to price | C23: % | D23: =D22/'Drivers'!$D$7-1
B24: Terminal value, % of enterprise value | C24: % | D24: =D17/D18
B25: Implied terminal EV / EBITDA | C25: x | D25: =D16/('Model'!R33+'Model'!R55)
B26: P/E at DCF value on FY27E EPS | C26: x | D26: =D22/'Model'!J47
B27: EV / EBIT today on FY26E | C27: x | D27: ='Drivers'!$D$19/'Model'!I33
B29: PRICE PATH | ACTIVE SCENARIO
B30: Exit P/E (NTM) | C30: x | D30: ='Drivers'!$D$45
B31: Years to exit 1 (end of 2028) | C31: yrs | D31: =('Drivers'!$D$11-'Drivers'!$D$8)/365
B32: FY29E EPS | C32: $ | D32: ='Model'!L47
B33: Price at the end of 2028 | C33: $ | D33: =D30*D32
B34: Price at exit / price today | C34: x | D34: =D33/'Drivers'!$D$7
B35: IRR to the end of 2028 | C35: % | D35: =D34^(1/D31)-1
B36: Entry price for the hurdle IRR to exit 1 | C36: $ | D36: =D33/(1+'Drivers'!$D$36)^D31
B37: Years to exit 2 (end of 2029) | C37: yrs | D37: =('Drivers'!$D$12-'Drivers'!$D$8)/365
B38: FY30E EPS | C38: $ | D38: ='Model'!M47
B39: Price at the end of 2029 | C39: $ | D39: =D30*D38
B40: IRR to the end of 2029 | C40: % | D40: =(D39/'Drivers'!$D$7)^(1/D37)-1
B42: DCF VALUE PER SHARE: TERMINAL GROWTH (DOWN) X WACC (ACROSS)
E43: =D22 | F43: ='Drivers'!$D$29+(0-2)*'Drivers'!$D$37 | G43: ='Drivers'!$D$29+(1-2)*'Drivers'!$D$37 | H43: ='Drivers'!$D$29+(2-2)*'Drivers'!$D$37 | I43: ='Drivers'!$D$29+(3-2)*'Drivers'!$D$37 | J43: ='Drivers'!$D$29+(4-2)*'Drivers'!$D$37
E44: =$D$15+(0-2)*'Drivers'!$D$38 | F44: =(SUMPRODUCT($I$9:$R$9,(1+F$43)^(-$I$10:$R$10))+$R$7*(1+$E44)/(F$43-$E44)*(1+F$43)^(-$R$10)+$D$19)/$D$21 | G44: =(SUMPRODUCT($I$9:$R$9,(1+G$43)^(-$I$10:$R$10))+$R$7*(1+$E44)/(G$43-$E44)*(1+G$43)^(-$R$10)+$D$19)/$D$21 | H44: =(SUMPRODUCT($I$9:$R$9,(1+H$43)^(-$I$10:$R$10))+$R$7*(1+$E44)/(H$43-$E44)*(1+H$43)^(-$R$10)+$D$19)/$D$21 | I44: =(SUMPRODUCT($I$9:$R$9,(1+I$43)^(-$I$10:$R$10))+$R$7*(1+$E44)/(I$43-$E44)*(1+I$43)^(-$R$10)+$D$19)/$D$21 | J44: =(SUMPRODUCT($I$9:$R$9,(1+J$43)^(-$I$10:$R$10))+$R$7*(1+$E44)/(J$43-$E44)*(1+J$43)^(-$R$10)+$D$19)/$D$21
...

Sheet Scenarios
B1: Netflix, Inc. | Scenarios
B2: Three complete chains, always live, independent of the Drivers switch. The comparison table feeds the Summary.
B3: Blue = input Black = formula Green = cross-sheet link $ in millions except per share; shares in millions (post-split)
B5: COMPARISON
F6: Bear | G6: Base | H6: Bull | I6: Weighted
B7: Probability | C7: % | F7: ='Drivers'!$F$43 | G7: ='Drivers'!$G$43 | H7: ='Drivers'!$H$43 | I7: =SUM(F7:H7)
B8: FY26E revenue growth | C8: % | F8: =I50 | G8: =I162 | H8: =I274
B9: FY27E revenue growth | C9: % | F9: =J50 | G9: =J162 | H9: =J274
B10: FY28E advertising revenue | C10: $mm | F10: =K51 | G10: =K163 | H10: =K275
B11: FY27E operating margin | C11: % | F11: =J67 | G11: =J179 | H11: =J291
B12: FY29E operating margin | C12: % | F12: =L67 | G12: =L179 | H12: =L291
B13: FY26E EPS, GAAP (with the fee) | C13: $ | F13: =I78 | G13: =I190 | H13: =I302 | I13: =SUMPRODUCT($F$7:$H$7,F13:H13)
B14: FY26E EPS ex the fee | C14: $ | F14: =I80 | G14: =I192 | H14: =I304 | I14: =SUMPRODUCT($F$7:$H$7,F14:H14)
B15: FY27E EPS | C15: $ | F15: =J80 | G15: =J192 | H15: =J304 | I15: =SUMPRODUCT($F$7:$H$7,F15:H15)
B16: FY29E EPS | C16: $ | F16: =L80 | G16: =L192 | H16: =L304 | I16: =SUMPRODUCT($F$7:$H$7,F16:H16)
B17: FY30E EPS | C17: $ | F17: =M80 | G17: =M192 | H17: =M304 | I17: =SUMPRODUCT($F$7:$H$7,F17:H17)
B18: FY29E revenue | C18: $mm | F18: =L49 | G18: =L161 | H18: =L273
B19: FY27E free cash flow | C19: $mm | F19: =J94 | G19: =J206 | H19: =J318
B20: FY27E share repurchases | C20: $mm | F20: =-J101 | G20: =-J213 | H20: =-J325
B21: FY29E diluted shares | C21: mm | F21: =L77 | G21: =L189 | H21: =L301
B22: Terminal growth | C22: % | F22: ='Drivers'!$F$44 | G22: ='Drivers'!$G$44 | H22: ='Drivers'!$H$44
B23: Implied terminal EV / EBITDA | C23: x | F23: =D130 | G23: =D242 | H23: =D354
B24: DCF value per share | C24: $ | F24: =D127 | G24: =D239 | H24: =D351 | I24: =SUMPRODUCT($F$7:$H$7,F24:H24)
B25: vs price | C25: % | F25: =F24/'Drivers'!$D$7-1 | G25: =G24/'Drivers'!$D$7-1 | H25: =H24/'Drivers'!$D$7-1 | I25: =I24/'Drivers'!$D$7-1
B26: Exit P/E (NTM) | C26: x | F26: =D135 | G26: =D247 | H26: =D359
B27: Price at the end of 2028 | C27: $ | F27: =D138 | G27: =D250 | H27: =D362 | I27: =SUMPRODUCT($F$7:$H$7,F27:H27)
B28: IRR to the end of 2028 | C28: % | F28: =D140 | G28: =D252 | H28: =D364 | I28: =(I27/'Drivers'!$D$7)^(1/D136)-1
B29: Price at the end of 2029 | C29: $ | F29: =D144 | G29: =D256 | H29: =D368 | I29: =SUMPRODUCT($F$7:$H$7,F29:H29)
B30: IRR to the end of 2029 | C30: % | F30: =D145 | G30: =D257 | H30: =D369 | I30: =(I29/'Drivers'!$D$7)^(1/D142)-1
B31: Entry price for the hurdle IRR (exit 1) | C31: $ | F31: =D141 | G31: =D253 | H31: =D365 | I31: =SUMPRODUCT($F$7:$H$7,F31:H31)
B36: BEAR CASE
B38: REVENUE | BEAR CASE
B39: Fiscal year (calendar) | F39: 2023 | G39: 2024 | H39: 2025 | I39: 2026 | J39: 2027 | K39: 2028 | L39: 2029 | M39: 2030 | N39: 2031 | O39: 2032 | P39: 2033 | Q39: 2034 | R39: 2035
B40: United States and Canada | C40: $mm | F40: ='Model'!F7 | G40: ='Model'!G7 | H40: ='Model'!H7 | I40: =H40*(1+I41) | J40: =I40*(1+J41) | K40: =J40*(1+K41) | L40: =K40*(1+L41) | M40: =L40*(1+M41) | N40: =M40*(1+N41) | O40: =N40*(1+O41) | P40: =O40*(1+P41) | ... R40: =Q40*(1+R41)
B41: y/y | C41: % | G41: ='Model'!G8 | H41: ='Model'!H8 | I41: ='Drivers'!I$69 | J41: ='Drivers'!J$69 | K41: ='Drivers'!K$69 | L41: ='Drivers'!L$69 | M41: ='Drivers'!M$69 | N41: ='Drivers'!N$69 | O41: ='Drivers'!O$69 | P41: ='Drivers'!P$69 | ... R41: ='Drivers'!R$69
B42: Europe, Middle East and Africa | C42: $mm | F42: ='Model'!F9 | G42: ='Model'!G9 | H42: ='Model'!H9 | I42: =H42*(1+I43) | J42: =I42*(1+J43) | K42: =J42*(1+K43) | L42: =K42*(1+L43) | M42: =L42*(1+M43) | N42: =M42*(1+N43) | O42: =N42*(1+O43) | P42: =O42*(1+P43) | ... R42: =Q42*(1+R43)
B43: y/y | C43: % | G43: ='Model'!G10 | H43: ='Model'!H10 | I43: ='Drivers'!I$72 | J43: ='Drivers'!J$72 | K43: ='Drivers'!K$72 | L43: ='Drivers'!L$72 | M43: ='Drivers'!M$72 | N43: ='Drivers'!N$72 | O43: ='Drivers'!O$72 | P43: ='Drivers'!P$72 | ... R43: ='Drivers'!R$72
B44: Latin America | C44: $mm | F44: ='Model'!F11 | G44: ='Model'!G11 | H44: ='Model'!H11 | I44: =H44*(1+I45) | J44: =I44*(1+J45) | K44: =J44*(1+K45) | L44: =K44*(1+L45) | M44: =L44*(1+M45) | N44: =M44*(1+N45) | O44: =N44*(1+O45) | P44: =O44*(1+P45) | ... R44: =Q44*(1+R45)
B45: y/y | C45: % | G45: ='Model'!G12 | H45: ='Model'!H12 | I45: ='Drivers'!I$75 | J45: ='Drivers'!J$75 | K45: ='Drivers'!K$75 | L45: ='Drivers'!L$75 | M45: ='Drivers'!M$75 | N45: ='Drivers'!N$75 | O45: ='Drivers'!O$75 | P45: ='Drivers'!P$75 | ... R45: ='Drivers'!R$75
B46: Asia-Pacific | C46: $mm | F46: ='Model'!F13 | G46: ='Model'!G13 | H46: ='Model'!H13 | I46: =H46*(1+I47) | J46: =I46*(1+J47) | K46: =J46*(1+K47) | L46: =K46*(1+L47) | M46: =L46*(1+M47) | N46: =M46*(1+N47) | O46: =N46*(1+O47) | P46: =O46*(1+P47) | ... R46: =Q46*(1+R47)
...

Sheet Sources
B1: Netflix, Inc. | Sources, judgments, open items
B2: Full register: outputs/research/nflx_model_assumptions.md
B3: Blue = input Black = formula Green = cross-sheet link $ in millions except per share; shares in millions (post-split)
B6: SOURCES
B7: FY2025 10-K (filed 2026-01-23): https://www.sec.gov/Archives/edgar/data/1065280/000106528026000034/nflx-20251231.htm
B8: Q3 2026 10-Q (filed 2026-10-21): https://www.sec.gov/Archives/edgar/data/1065280/000106528026000291/nflx-20260930.htm
B9: Q3 2026 shareholder letter (8-K Ex. 99.1, 2026-10-20): https://www.sec.gov/Archives/edgar/data/0001065280/000106528026000290/ex991_q326.htm
B10: Q2 2026 letter (2026-07-16), Q1 2026 letter (2026-04-16), Q4 2025 letter (2026-01-20), Q2 2026 10-Q (regional revenue), 8-K Ex. 99.1 on EDGAR.
B11: SEC XBRL company facts, CIK 1065280 (annual and quarterly lines, content obligations, repurchase authorization): https://data.sec.gov/api/xbrl/companyfacts/CIK0001065280.json
B12: Price: Nasdaq close 2026-10-23 $66.29. UST 10Y 4.99% (2026-10-23). Street: Yahoo Finance consensus and price targets 2026-10-23.
B13: Earnings Desk fundamentals for NFLX (SEC facts, closes, Nasdaq consensus; data/earnings_market/fund_NFLX.json) for the 10-year P/E band.
B15: CONTEXT (FACTS)
... B39: 2026-10-23 First build. Not wired into theses.yaml, the Holdings tab or filing_review; a watch model. Projections also feed the Earnings Desk NFLX profile.
